Workbook

Sheet Carta Gantt
A1: Carta Gantt maestra v6 - Optimizacion del prestow de celulosa, Puerto Lirquen
A2: 7 semanas de trabajo + semana 8 de colchon. Tareas generales; el detalle esta en las hojas de cada entregable.
A3: Columnas K, L y M: avance acumulado de cada entregable al cerrar la semana en que termina esa tarea.
M4: Semana
A5: ID | B5: Fase | C5: Tarea | D5: Artefacto verificable | E5: Depende de | F5: Inicio | G5: Duracion | H5: Fin | I5: Critica | J5: % Inf. Tecnico | K5: % Inf. Academico | L5: % Pagina web | M5: 1 | N5: 2 | O5: 3 | P5: 4 | Q5: 5 | R5: 6 | S5: 7 | T5: 8
A6: 1 | B6: F0. Encuadre | C6: Registro de supuestos: los 6 no resueltos, con justificacion e impacto | D6: Tabla de supuestos versionada | E6: - | F6: 1 | G6: 1 | H6: =F6+G6-1 -> 1 | I6: Si | J6: =SUMPRODUCT(($H$6:$H$41<=$H6)*Aportes!$C$2:$C$37) -> 0.07 | K6: =SUMPRODUCT(($H$6:$H$41<=$H6)*Aportes!$D$2:$D$37) -> 0.13 | L6: =SUMPRODUCT(($H$6:$H$41<=$H6)*Aportes!$E$2:$E$37) -> 0.04 | M6: =IF(AND(M$5>=$F6,M$5<$F6+$G6),1,"") -> 1 | N6: =IF(AND(N$5>=$F6,N$5<$F6+$G6),1,"") | O6: =IF(AND(O$5>=$F6,O$5<$F6+$G6),1,"") | P6: =IF(AND(P$5>=$F6,P$5<$F6+$G6),1,"") | Q6: =IF(AND(Q$5>=$F6,Q$5<$F6+$G6),1,"") | R6: =IF(AND(R$5>=$F6,R$5<$F6+$G6),1,"") | S6: =IF(AND(S$5>=$F6,S$5<$F6+$G6),1,"") | T6: =IF(AND(T$5>=$F6,T$5<$F6+$G6),1,"")
A7: 2 | B7: F0. Encuadre | C7: Congelar el caso base: Kiwi Arrow, hoja PRESTOW N 06 | D7: Una sola fuente de verdad declarada | E7: - | F7: 1 | G7: 1 | H7: =F7+G7-1 -> 1 | I7: Si | J7: =SUMPRODUCT(($H$6:$H$41<=$H7)*Aportes!$C$2:$C$37) -> 0.07 | K7: =SUMPRODUCT(($H$6:$H$41<=$H7)*Aportes!$D$2:$D$37) -> 0.13 | L7: =SUMPRODUCT(($H$6:$H$41<=$H7)*Aportes!$E$2:$E$37) -> 0.04 | M7: =IF(AND(M$5>=$F7,M$5<$F7+$G7),1,"") -> 1 | N7: =IF(AND(N$5>=$F7,N$5<$F7+$G7),1,"") | O7: =IF(AND(O$5>=$F7,O$5<$F7+$G7),1,"") | P7: =IF(AND(P$5>=$F7,P$5<$F7+$G7),1,"") | Q7: =IF(AND(Q$5>=$F7,Q$5<$F7+$G7),1,"") | R7: =IF(AND(R$5>=$F7,R$5<$F7+$G7),1,"") | S7: =IF(AND(S$5>=$F7,S$5<$F7+$G7),1,"") | T7: =IF(AND(T$5>=$F7,T$5<$F7+$G7),1,"")
A8: 3 | B8: F0. Encuadre | C8: Escribir la propuesta de valor: velocidad y repetibilidad, no mejor calidad | D8: Parrafo que ira al Resumen Ejecutivo | E8: - | F8: 1 | G8: 1 | H8: =F8+G8-1 -> 1 | I8: Si | J8: =SUMPRODUCT(($H$6:$H$41<=$H8)*Aportes!$C$2:$C$37) -> 0.07 | K8: =SUMPRODUCT(($H$6:$H$41<=$H8)*Aportes!$D$2:$D$37) -> 0.13 | L8: =SUMPRODUCT(($H$6:$H$41<=$H8)*Aportes!$E$2:$E$37) -> 0.04 | M8: =IF(AND(M$5>=$F8,M$5<$F8+$G8),1,"") -> 1 | N8: =IF(AND(N$5>=$F8,N$5<$F8+$G8),1,"") | O8: =IF(AND(O$5>=$F8,O$5<$F8+$G8),1,"") | P8: =IF(AND(P$5>=$F8,P$5<$F8+$G8),1,"") | Q8: =IF(AND(Q$5>=$F8,Q$5<$F8+$G8),1,"") | R8: =IF(AND(R$5>=$F8,R$5<$F8+$G8),1,"") | S8: =IF(AND(S$5>=$F8,S$5<$F8+$G8),1,"") | T8: =IF(AND(T$5>=$F8,T$5<$F8+$G8),1,"")
A9: 4 | B9: F1. Datos | C9: Desocultar hojas y separar Kiwi Arrow de Misago y Eagle Arrow | D9: Inventario de hojas por buque | E9: - | F9: 1 | G9: 1 | H9: =F9+G9-1 -> 1 | I9: No | J9: =SUMPRODUCT(($H$6:$H$41<=$H9)*Aportes!$C$2:$C$37) -> 0.07 | K9: =SUMPRODUCT(($H$6:$H$41<=$H9)*Aportes!$D$2:$D$37) -> 0.13 | L9: =SUMPRODUCT(($H$6:$H$41<=$H9)*Aportes!$E$2:$E$37) -> 0.04 | M9: =IF(AND(M$5>=$F9,M$5<$F9+$G9),1,"") -> 1 | N9: =IF(AND(N$5>=$F9,N$5<$F9+$G9),1,"") | O9: =IF(AND(O$5>=$F9,O$5<$F9+$G9),1,"") | P9: =IF(AND(P$5>=$F9,P$5<$F9+$G9),1,"") | Q9: =IF(AND(Q$5>=$F9,Q$5<$F9+$G9),1,"") | R9: =IF(AND(R$5>=$F9,R$5<$F9+$G9),1,"") | S9: =IF(AND(S$5>=$F9,S$5<$F9+$G9),1,"") | T9: =IF(AND(T$5>=$F9,T$5<$F9+$G9),1,"")
A10: 5 | B10: F1. Datos | C10: Extraer el prestow a CSV estructurado | D10: CSV bodega-plan-destino-producto | E10: 4 | F10: 1 | G10: 1 | H10: =F10+G10-1 -> 1 | I10: Si | J10: =SUMPRODUCT(($H$6:$H$41<=$H10)*Aportes!$C$2:$C$37) -> 0.07 | K10: =SUMPRODUCT(($H$6:$H$41<=$H10)*Aportes!$D$2:$D$37) -> 0.13 | L10: =SUMPRODUCT(($H$6:$H$41<=$H10)*Aportes!$E$2:$E$37) -> 0.04 | M10: =IF(AND(M$5>=$F10,M$5<$F10+$G10),1,"") -> 1 | N10: =IF(AND(N$5>=$F10,N$5<$F10+$G10),1,"") | O10: =IF(AND(O$5>=$F10,O$5<$F10+$G10),1,"") | P10: =IF(AND(P$5>=$F10,P$5<$F10+$G10),1,"") | Q10: =IF(AND(Q$5>=$F10,Q$5<$F10+$G10),1,"") | R10: =IF(AND(R$5>=$F10,R$5<$F10+$G10),1,"") | S10: =IF(AND(S$5>=$F10,S$5<$F10+$G10),1,"") | T10: =IF(AND(T$5>=$F10,T$5<$F10+$G10),1,"")
A11: 6 | B11: F1. Datos | C11: Leer los dibujos de planimetria y tabular unidades por plan | D11: CSV unid/plan por bodega, producto y altura | E11: 4 | F11: 1 | G11: 2 | H11: =F11+G11-1 -> 2 | I11: Si | J11: =SUMPRODUCT(($H$6:$H$41<=$H11)*Aportes!$C$2:$C$37) -> 0.31 | K11: =SUMPRODUCT(($H$6:$H$41<=$H11)*Aportes!$D$2:$D$37) -> 0.53 | L11: =SUMPRODUCT(($H$6:$H$41<=$H11)*Aportes!$E$2:$E$37) -> 0.14 | M11: =IF(AND(M$5>=$F11,M$5<$F11+$G11),1,"") -> 1 | N11: =IF(AND(N$5>=$F11,N$5<$F11+$G11),1,"") -> 1 | O11: =IF(AND(O$5>=$F11,O$5<$F11+$G11),1,"") | P11: =IF(AND(P$5>=$F11,P$5<$F11+$G11),1,"") | Q11: =IF(AND(Q$5>=$F11,Q$5<$F11+$G11),1,"") | R11: =IF(AND(R$5>=$F11,R$5<$F11+$G11),1,"") | S11: =IF(AND(S$5>=$F11,S$5<$F11+$G11),1,"") | T11: =IF(AND(T$5>=$F11,T$5<$F11+$G11),1,"")
A12: 7 | B12: F1. Datos | C12: Registrar inconsistencias entre celdas auxiliares y dibujos | D12: Bitacora de discrepancias | E12: 6 | F12: 2 | G12: 1 | H12: =F12+G12-1 -> 2 | I12: No | J12: =SUMPRODUCT(($H$6:$H$41<=$H12)*Aportes!$C$2:$C$37) -> 0.31 | K12: =SUMPRODUCT(($H$6:$H$41<=$H12)*Aportes!$D$2:$D$37) -> 0.53 | L12: =SUMPRODUCT(($H$6:$H$41<=$H12)*Aportes!$E$2:$E$37) -> 0.14 | M12: =IF(AND(M$5>=$F12,M$5<$F12+$G12),1,"") | N12: =IF(AND(N$5>=$F12,N$5<$F12+$G12),1,"") -> 1 | O12: =IF(AND(O$5>=$F12,O$5<$F12+$G12),1,"") | P12: =IF(AND(P$5>=$F12,P$5<$F12+$G12),1,"") | Q12: =IF(AND(Q$5>=$F12,Q$5<$F12+$G12),1,"") | R12: =IF(AND(R$5>=$F12,R$5<$F12+$G12),1,"") | S12: =IF(AND(S$5>=$F12,S$5<$F12+$G12),1,"") | T12: =IF(AND(T$5>=$F12,T$5<$F12+$G12),1,"")
A13: 8 | B13: F1. Datos | C13: Diccionario de datos: campos, tipos, rangos y reglas | D13: Diccionario para el anexo | E13: 5,6 | F13: 2 | G13: 1 | H13: =F13+G13-1 -> 2 | I13: No | J13: =SUMPRODUCT(($H$6:$H$41<=$H13)*Aportes!$C$2:$C$37) -> 0.31 | K13: =SUMPRODUCT(($H$6:$H$41<=$H13)*Aportes!$D$2:$D$37) -> 0.53 | L13: =SUMPRODUCT(($H$6:$H$41<=$H13)*Aportes!$E$2:$E$37) -> 0.14 | M13: =IF(AND(M$5>=$F13,M$5<$F13+$G13),1,"") | N13: =IF(AND(N$5>=$F13,N$5<$F13+$G13),1,"") -> 1 | O13: =IF(AND(O$5>=$F13,O$5<$F13+$G13),1,"") | P13: =IF(AND(P$5>=$F13,P$5<$F13+$G13),1,"") | Q13: =IF(AND(Q$5>=$F13,Q$5<$F13+$G13),1,"") | R13: =IF(AND(R$5>=$F13,R$5<$F13+$G13),1,"") | S13: =IF(AND(S$5>=$F13,S$5<$F13+$G13),1,"") | T13: =IF(AND(T$5>=$F13,T$5<$F13+$G13),1,"")
A14: 9 | B14: F2. Metodo | C14: Leer el survey de estiba y 4 a 6 trabajos adicionales | D14: Fichas de lectura | E14: - | F14: 1 | G14: 2 | H14: =F14+G14-1 -> 2 | I14: No | J14: =SUMPRODUCT(($H$6:$H$41<=$H14)*Aportes!$C$2:$C$37) -> 0.31 | K14: =SUMPRODUCT(($H$6:$H$41<=$H14)*Aportes!$D$2:$D$37) -> 0.53 | L14: =SUMPRODUCT(($H$6:$H$41<=$H14)*Aportes!$E$2:$E$37) -> 0.14 | M14: =IF(AND(M$5>=$F14,M$5<$F14+$G14),1,"") -> 1 | N14: =IF(AND(N$5>=$F14,N$5<$F14+$G14),1,"") -> 1 | O14: =IF(AND(O$5>=$F14,O$5<$F14+$G14),1,"") | P14: =IF(AND(P$5>=$F14,P$5<$F14+$G14),1,"") | Q14: =IF(AND(Q$5>=$F14,Q$5<$F14+$G14),1,"") | R14: =IF(AND(R$5>=$F14,R$5<$F14+$G14),1,"") | S14: =IF(AND(S$5>=$F14,S$5<$F14+$G14),1,"") | T14: =IF(AND(T$5>=$F14,T$5<$F14+$G14),1,"")
A15: 10 | B15: F2. Metodo | C15: Tabla comparativa modelo / objetivo / metodo / aplicabilidad a Lirquen | D15: Tabla comparativa | E15: 9 | F15: 2 | G15: 1 | H15: =F15+G15-1 -> 2 | I15: No | J15: =SUMPRODUCT(($H$6:$H$41<=$H15)*Aportes!$C$2:$C$37) -> 0.31 | K15: =SUMPRODUCT(($H$6:$H$41<=$H15)*Aportes!$D$2:$D$37) -> 0.53 | L15: =SUMPRODUCT(($H$6:$H$41<=$H15)*Aportes!$E$2:$E$37) -> 0.14 | M15: =IF(AND(M$5>=$F15,M$5<$F15+$G15),1,"") | N15: =IF(AND(N$5>=$F15,N$5<$F15+$G15),1,"") -> 1 | O15: =IF(AND(O$5>=$F15,O$5<$F15+$G15),1,"") | P15: =IF(AND(P$5>=$F15,P$5<$F15+$G15),1,"") | Q15: =IF(AND(Q$5>=$F15,Q$5<$F15+$G15),1,"") | R15: =IF(AND(R$5>=$F15,R$5<$F15+$G15),1,"") | S15: =IF(AND(S$5>=$F15,S$5<$F15+$G15),1,"") | T15: =IF(AND(T$5>=$F15,T$5<$F15+$G15),1,"")
A16: 11 | B16: F2. Metodo | C16: Seleccion analitica del metodo, con pros, contras y justificacion | D16: Memo de seleccion de metodo | E16: 10 | F16: 2 | G16: 1 | H16: =F16+G16-1 -> 2 | I16: Si | J16: =SUMPRODUCT(($H$6:$H$41<=$H16)*Aportes!$C$2:$C$37) -> 0.31 | K16: =SUMPRODUCT(($H$6:$H$41<=$H16)*Aportes!$D$2:$D$37) -> 0.53 | L16: =SUMPRODUCT(($H$6:$H$41<=$H16)*Aportes!$E$2:$E$37) -> 0.14 | M16: =IF(AND(M$5>=$F16,M$5<$F16+$G16),1,"") | N16: =IF(AND(N$5>=$F16,N$5<$F16+$G16),1,"") -> 1 | O16: =IF(AND(O$5>=$F16,O$5<$F16+$G16),1,"") | P16: =IF(AND(P$5>=$F16,P$5<$F16+$G16),1,"") | Q16: =IF(AND(Q$5>=$F16,Q$5<$F16+$G16),1,"") | R16: =IF(AND(R$5>=$F16,R$5<$F16+$G16),1,"") | S16: =IF(AND(S$5>=$F16,S$5<$F16+$G16),1,"") | T16: =IF(AND(T$5>=$F16,T$5<$F16+$G16),1,"")
A17: 12 | B17: F3. Definicion | C17: Definir funcion objetivo y alcance del sistema (que hace y que NO hace) | D17: Una pagina acordada por el grupo | E17: 1,2,3 | F17: 2 | G17: 1 | H17: =F17+G17-1 -> 2 | I17: Si | J17: =SUMPRODUCT(($H$6:$H$41<=$H17)*Aportes!$C$2:$C$37) -> 0.31 | K17: =SUMPRODUCT(($H$6:$H$41<=$H17)*Aportes!$D$2:$D$37) -> 0.53 | L17: =SUMPRODUCT(($H$6:$H$41<=$H17)*Aportes!$E$2:$E$37) -> 0.14 | M17: =IF(AND(M$5>=$F17,M$5<$F17+$G17),1,"") | N17: =IF(AND(N$5>=$F17,N$5<$F17+$G17),1,"") -> 1 | O17: =IF(AND(O$5>=$F17,O$5<$F17+$G17),1,"") | P17: =IF(AND(P$5>=$F17,P$5<$F17+$G17),1,"") | Q17: =IF(AND(Q$5>=$F17,Q$5<$F17+$G17),1,"") | R17: =IF(AND(R$5>=$F17,R$5<$F17+$G17),1,"") | S17: =IF(AND(S$5>=$F17,S$5<$F17+$G17),1,"") | T17: =IF(AND(T$5>=$F17,T$5<$F17+$G17),1,"")
... A41: 36 | B41: F8. Colchon | C41: Semana de colchon: solo correcciones, cero funcionalidad nueva | D41: Entrega enviada | E41: 35 | F41: 8 | G41: 1 | H41: =F41+G41-1 -> 8 | I41: Si | J41: =SUMPRODUCT(($H$6:$H$41<=$H41)*Aportes!$C$2:$C$37) -> 1 | K41: =SUMPRODUCT(($H$6:$H$41<=$H41)*Aportes!$D$2:$D$37) -> 1 | L41: =SUMPRODUCT(($H$6:$H$41<=$H41)*Aportes!$E$2:$E$37) -> 1 | M41: =IF(AND(M$5>=$F41,M$5<$F41+$G41),1,"") | N41: =IF(AND(N$5>=$F41,N$5<$F41+$G41),1,"") | O41: =IF(AND(O$5>=$F41,O$5<$F41+$G41),1,"") | P41: =IF(AND(P$5>=$F41,P$5<$F41+$G41),1,"") | Q41: =IF(AND(Q$5>=$F41,Q$5<$F41+$G41),1,"") | R41: =IF(AND(R$5>=$F41,R$5<$F41+$G41),1,"") | S41: =IF(AND(S$5>=$F41,S$5<$F41+$G41),1,"") | T41: =IF(AND(T$5>=$F41,T$5<$F41+$G41),1,"") -> 1
A43: Leyenda
A44: Naranjo = ruta critica. Verde = colchon. Gris = tiene holgura. Amarillo = celda editable.
A45: Hojas del libro: esta maestra, una por entregable con sus subtareas, y Aportes con los pesos.
A47: Supuestos de esta version (deben quedar en el registro de la tarea 1)
A48: 1. No habra contacto con la contraparte. Las 6 incognitas abiertas se resuelven por supuesto declarado.
A49: 2. El Puerto fija el tonelaje por bodega. Informacion del grupo, sin confirmar.
A50: 3. Los rendimientos t/h se toman del Excel como parametro. Por eso la tarea 26 es obligatoria.
A51: 4. Los pares de bodegas por cuadrilla se asumen fijos: (8+7), (6+5), (4+3), (2+1).
A52: 5. Una unidad pesa 2,02 t con huella de 0,84 x 1,47 m. Factor de estiba implicito 1,05 m3/t.
A53: 6. La duracion de la tarea 6 es estimada, no medida. Es el mayor riesgo de atraso del proyecto.
A54: 7. El nucleo de optimizacion y la interfaz se entregan como pagina web, no como programa instalable.
A56: Reglas de operacion
... A59: Despues del congelamiento (tarea 28) no se agrega funcionalidad, aunque sobre tiempo.

Sheet Responsables
A1: Responsables del proyecto
A2: Un pivote y cuatro encargados. El encargado responde por que el entregable se cumpla; no necesariamente lo ejecuta.
A4: EL EQUIPO
A5: Rol | B5: Nombre | C5: Frente del que responde | D5: Qué significa responder por él
A6: Pivote | C6: Todo el proyecto | D6: Acompaña a los cuatro encargados y conecta las tareas entre sí. No ejecuta un frente propio: su trabajo es que las piezas encajen. Detecta cuando un frente depende de otro y nadie lo dijo.
A7: Encargado 1 | C7: Datos y Metodo (F1, F2, F3) | D7: Que existan los CSV, el diccionario, las fichas de lectura, el memo de metodo, la funcion objetivo, los KPIs y el modelo matematico. Alimenta a los otros tres frentes.
A8: Encargado 2 | C8: Pagina web (F4, F5) | D8: Que el sistema exista, corra de punta a punta y este desplegado con su caso demo. Incluye el nucleo de optimizacion y la interfaz.
A9: Encargado 3 | C9: Informe Tecnico | D9: Que las 28 subtareas del informe tecnico existan, respeten su limite de paginas y no se contradigan entre si. Incluye el manual de usuario.
A10: Encargado 4 | C10: Informe Academico | D10: Que las 29 subtareas del informe academico existan. Incluye la bitacora semanal, que es el unico insumo de la seccion 2.
A13: QUE ENTREGABLE CUBRE CADA FASE
A14: Las fases F0, F6, F7 y F8 no tienen un encargado unico: se reparten segun se indica.
A15: Fase | B15: Tareas | C15: Encargado | D15: Observacion
A16: F0. Encuadre | B16: 1, 2, 3 | C16: Los cinco | D16: Las tres son decisiones del grupo completo. Si las toma una persona sola, los otros cuatro escriben sobre supuestos distintos durante cinco semanas.
A17: F1. Datos | B17: 4 a 8 | C17: Encargado 1 | D17: Alimenta al nucleo y a la seccion de tratamiento de datos del informe academico.
A18: F2. Metodo | B18: 9, 10, 11 | C18: Encargado 1 | D18: El memo de la tarea 11 vale 30 puntos del informe academico.
A19: F3. Definicion | B19: 12, 13, 14 | C19: Encargado 1 | D19: La tarea 12 es del grupo completo aunque el encargado 1 la conduzca: define lo que los cinco van a citar.
A20: F4. Nucleo | B20: 15 a 18 | C20: Encargado 2 | D20: Packer, asignador, generador de instancias e integracion.
A21: F5. Pagina web | B21: 19 a 23 | C21: Encargado 2 | D21: Entrada de datos, interfaz, salida y despliegue.
A22: F6. Validacion | B22: 24 a 28 | C22: Encargado 2 ejecuta, 3 y 4 documentan | D22: El codigo lo corre quien lo escribio; los resultados los documentan los encargados de informes.
A23: F7. Documentacion | B23: 29 a 35 | C23: Encargados 3 y 4 | D23: La tarea 29, bitacora, la lleva el encargado 4 pero rotando quien la completa cada semana.
A24: F8. Colchon | B24: 36 | C24: Pivote | D24: Coordina el cierre. Nadie planifica trabajo dentro de esta semana.
A27: EL ROL PIVOTE, EN CONCRETO
A28: Un pivote sin tareas propias se diluye. Estos son los puntos donde su trabajo es verificable.
A29: Semana | B29: Punto de control del pivote | C29: Por que ahi
A30: 1 | B30: Que las tres tareas de encuadre salgan con artefacto escrito, no con acuerdo verbal | C30: Un acuerdo verbal del lunes no sobrevive a la semana 4.
A31: 1 | B31: Que se cronometre la lectura de un plano y se extrapole | C31: La tarea 6 es la unica cuya duracion nunca se midio. Es el mayor riesgo de atraso.
A32: 2 | B32: Que el memo de metodo tenga alternativas comparadas, no una frase | C32: Es el rubro de 30 puntos. Sin proceso documentado no hay nada que evaluar.
A33: 3 | B33: Que el stack y los contratos se cierren antes de que alguien escriba codigo | C33: Si los contratos no estan escritos, la integracion de la semana 4 se convierte en cirugia.
A34: 4 | B34: Que el esqueleto de integracion corra, aunque sea feo | C34: Responde una pregunta binaria mientras queda una semana liviana para reaccionar.
A35: 5 | B35: Que la especificacion de entrada este cerrada | C35: El manual de usuario se escribe en paralelo y no puede hacerlo a ciegas.
A36: 6 | B36: Que las cifras del informe tecnico y del academico coincidan entre si | C36: El resultado del resumen ejecutivo, la comparacion y la captura del manual deben ser el mismo numero.
A37: 7 | B37: Que el congelamiento se respete | C37: Despues de esa marca, cualquier cambio deja la documentacion describiendo un sistema que ya no existe.
A40: REGLAS DEL ESQUEMA
A41: 1. El encargado responde por que el entregable se cumpla, no por ejecutarlo solo. Puede delegar la produccion; no puede delegar la responsabilidad.
A42: 2. Nadie marca una tarea como terminada salvo su encargado, y solo contra el artefacto verificable.
A43: 3. El pivote no ejecuta un frente propio. Si termina programando o redactando, el equipo perdio su unico rol de coordinacion.
A44: 4. La bitacora la completa una persona distinta cada semana, aunque el encargado 4 responda por que exista.
A45: 5. Las tres tareas de encuadre (F0) no tienen encargado: son del grupo completo, en una sola reunion.
A46: 6. Si un encargado detecta que su frente depende de otro y eso no estaba previsto, se lo dice al pivote antes de reprogramar nada.
A48: Carga estimada por frente, para calibrar el reparto
...

Sheet Informe Tecnico
A1: Carta Gantt - Informe Tecnico y Manual de Usuario
A2: Subtareas que componen este entregable. La columna 'Tarea maestra' apunta al ID de la hoja Carta Gantt.
J3: Semana
A4: ID | B4: Seccion | C4: Subtarea | D4: Artefacto | E4: Tarea maestra | F4: Inicio | G4: Duracion | H4: Fin | I4: Critica | J4: 1 | K4: 2 | L4: 3 | M4: 4 | N4: 5 | O4: 6 | P4: 7 | Q4: 8
A5: 1 | B5: 1. Resumen Ejecutivo | C5: Redactar problema, tipo de solucion, beneficios y resultado principal | D5: 1 pagina cerrada | E5: 3 | F5: 6 | G5: 1 | H5: =F5+G5-1 -> 6 | I5: Si | J5: =IF(AND(J$4>=$F5,J$4<$F5+$G5),1,"") | K5: =IF(AND(K$4>=$F5,K$4<$F5+$G5),1,"") | L5: =IF(AND(L$4>=$F5,L$4<$F5+$G5),1,"") | M5: =IF(AND(M$4>=$F5,M$4<$F5+$G5),1,"") | N5: =IF(AND(N$4>=$F5,N$4<$F5+$G5),1,"") | O5: =IF(AND(O$4>=$F5,O$4<$F5+$G5),1,"") -> 1 | P5: =IF(AND(P$4>=$F5,P$4<$F5+$G5),1,"") | Q5: =IF(AND(Q$4>=$F5,Q$4<$F5+$G5),1,"")
A6: 2 | B6: 2. Problema y Alcance | C6: Redactar descripcion del sistema y stakeholders | D6: Seccion redactada | E6: 12 | F6: 3 | G6: 1 | H6: =F6+G6-1 -> 3 | I6: Si | J6: =IF(AND(J$4>=$F6,J$4<$F6+$G6),1,"") | K6: =IF(AND(K$4>=$F6,K$4<$F6+$G6),1,"") | L6: =IF(AND(L$4>=$F6,L$4<$F6+$G6),1,"") -> 1 | M6: =IF(AND(M$4>=$F6,M$4<$F6+$G6),1,"") | N6: =IF(AND(N$4>=$F6,N$4<$F6+$G6),1,"") | O6: =IF(AND(O$4>=$F6,O$4<$F6+$G6),1,"") | P6: =IF(AND(P$4>=$F6,P$4<$F6+$G6),1,"") | Q6: =IF(AND(Q$4>=$F6,Q$4<$F6+$G6),1,"")
A7: 3 | B7: 2. Problema y Alcance | C7: Redactar restricciones consideradas y supuestos del negocio | D7: Seccion redactada | E7: 1 | F7: 3 | G7: 1 | H7: =F7+G7-1 -> 3 | I7: Si | J7: =IF(AND(J$4>=$F7,J$4<$F7+$G7),1,"") | K7: =IF(AND(K$4>=$F7,K$4<$F7+$G7),1,"") | L7: =IF(AND(L$4>=$F7,L$4<$F7+$G7),1,"") -> 1 | M7: =IF(AND(M$4>=$F7,M$4<$F7+$G7),1,"") | N7: =IF(AND(N$4>=$F7,N$4<$F7+$G7),1,"") | O7: =IF(AND(O$4>=$F7,O$4<$F7+$G7),1,"") | P7: =IF(AND(P$4>=$F7,P$4<$F7+$G7),1,"") | Q7: =IF(AND(Q$4>=$F7,Q$4<$F7+$G7),1,"")
A8: 4 | B8: 2. Problema y Alcance | C8: Redactar que hace y que NO hace el sistema, con limites de tamano | D8: Seccion redactada | E8: 12 | F8: 3 | G8: 1 | H8: =F8+G8-1 -> 3 | I8: Si | J8: =IF(AND(J$4>=$F8,J$4<$F8+$G8),1,"") | K8: =IF(AND(K$4>=$F8,K$4<$F8+$G8),1,"") | L8: =IF(AND(L$4>=$F8,L$4<$F8+$G8),1,"") -> 1 | M8: =IF(AND(M$4>=$F8,M$4<$F8+$G8),1,"") | N8: =IF(AND(N$4>=$F8,N$4<$F8+$G8),1,"") | O8: =IF(AND(O$4>=$F8,O$4<$F8+$G8),1,"") | P8: =IF(AND(P$4>=$F8,P$4<$F8+$G8),1,"") | Q8: =IF(AND(Q$4>=$F8,Q$4<$F8+$G8),1,"")
A9: 5 | B9: 3. Objetivos | C9: Redactar que optimiza o mejora el software | D9: 1 pagina cerrada | E9: 12 | F9: 3 | G9: 1 | H9: =F9+G9-1 -> 3 | I9: Si | J9: =IF(AND(J$4>=$F9,J$4<$F9+$G9),1,"") | K9: =IF(AND(K$4>=$F9,K$4<$F9+$G9),1,"") | L9: =IF(AND(L$4>=$F9,L$4<$F9+$G9),1,"") -> 1 | M9: =IF(AND(M$4>=$F9,M$4<$F9+$G9),1,"") | N9: =IF(AND(N$4>=$F9,N$4<$F9+$G9),1,"") | O9: =IF(AND(O$4>=$F9,O$4<$F9+$G9),1,"") | P9: =IF(AND(P$4>=$F9,P$4<$F9+$G9),1,"") | Q9: =IF(AND(Q$4>=$F9,Q$4<$F9+$G9),1,"")
A10: 6 | B10: 4. Modelo y Metodo | C10: Explicar el modelo en texto para lector no experto en optimizacion | D10: Seccion redactada | E10: 14 | F10: 3 | G10: 2 | H10: =F10+G10-1 -> 4 | I10: Si | J10: =IF(AND(J$4>=$F10,J$4<$F10+$G10),1,"") | K10: =IF(AND(K$4>=$F10,K$4<$F10+$G10),1,"") | L10: =IF(AND(L$4>=$F10,L$4<$F10+$G10),1,"") -> 1 | M10: =IF(AND(M$4>=$F10,M$4<$F10+$G10),1,"") -> 1 | N10: =IF(AND(N$4>=$F10,N$4<$F10+$G10),1,"") | O10: =IF(AND(O$4>=$F10,O$4<$F10+$G10),1,"") | P10: =IF(AND(P$4>=$F10,P$4<$F10+$G10),1,"") | Q10: =IF(AND(Q$4>=$F10,Q$4<$F10+$G10),1,"")
A11: 7 | B11: 4. Modelo y Metodo | C11: Anexar el modelo matematico formal | D11: Anexo referenciado | E11: 14 | F11: 4 | G11: 1 | H11: =F11+G11-1 -> 4 | I11: No | J11: =IF(AND(J$4>=$F11,J$4<$F11+$G11),1,"") | K11: =IF(AND(K$4>=$F11,K$4<$F11+$G11),1,"") | L11: =IF(AND(L$4>=$F11,L$4<$F11+$G11),1,"") | M11: =IF(AND(M$4>=$F11,M$4<$F11+$G11),1,"") -> 1 | N11: =IF(AND(N$4>=$F11,N$4<$F11+$G11),1,"") | O11: =IF(AND(O$4>=$F11,O$4<$F11+$G11),1,"") | P11: =IF(AND(P$4>=$F11,P$4<$F11+$G11),1,"") | Q11: =IF(AND(Q$4>=$F11,Q$4<$F11+$G11),1,"")
A12: 8 | B12: 4. Modelo y Metodo | C12: Describir metodos seleccionados con referencias y adaptaciones | D12: Seccion con citas APA 7 | E12: 11 | F12: 3 | G12: 1 | H12: =F12+G12-1 -> 3 | I12: Si | J12: =IF(AND(J$4>=$F12,J$4<$F12+$G12),1,"") | K12: =IF(AND(K$4>=$F12,K$4<$F12+$G12),1,"") | L12: =IF(AND(L$4>=$F12,L$4<$F12+$G12),1,"") -> 1 | M12: =IF(AND(M$4>=$F12,M$4<$F12+$G12),1,"") | N12: =IF(AND(N$4>=$F12,N$4<$F12+$G12),1,"") | O12: =IF(AND(O$4>=$F12,O$4<$F12+$G12),1,"") | P12: =IF(AND(P$4>=$F12,P$4<$F12+$G12),1,"") | Q12: =IF(AND(Q$4>=$F12,Q$4<$F12+$G12),1,"")
A13: 9 | B13: 4. Modelo y Metodo | C13: Dibujar la arquitectura conceptual del metodo de solucion | D13: Diagrama | E13: 11 | F13: 4 | G13: 1 | H13: =F13+G13-1 -> 4 | I13: Si | J13: =IF(AND(J$4>=$F13,J$4<$F13+$G13),1,"") | K13: =IF(AND(K$4>=$F13,K$4<$F13+$G13),1,"") | L13: =IF(AND(L$4>=$F13,L$4<$F13+$G13),1,"") | M13: =IF(AND(M$4>=$F13,M$4<$F13+$G13),1,"") -> 1 | N13: =IF(AND(N$4>=$F13,N$4<$F13+$G13),1,"") | O13: =IF(AND(O$4>=$F13,O$4<$F13+$G13),1,"") | P13: =IF(AND(P$4>=$F13,P$4<$F13+$G13),1,"") | Q13: =IF(AND(Q$4>=$F13,Q$4<$F13+$G13),1,"")
A14: 10 | B14: 4. Modelo y Metodo | C14: Escribir pseudocodigo o flujo logico de cada seccion del metodo | D14: Pseudocodigo en anexo | E14: 11 | F14: 4 | G14: 1 | H14: =F14+G14-1 -> 4 | I14: Si | J14: =IF(AND(J$4>=$F14,J$4<$F14+$G14),1,"") | K14: =IF(AND(K$4>=$F14,K$4<$F14+$G14),1,"") | L14: =IF(AND(L$4>=$F14,L$4<$F14+$G14),1,"") | M14: =IF(AND(M$4>=$F14,M$4<$F14+$G14),1,"") -> 1 | N14: =IF(AND(N$4>=$F14,N$4<$F14+$G14),1,"") | O14: =IF(AND(O$4>=$F14,O$4<$F14+$G14),1,"") | P14: =IF(AND(P$4>=$F14,P$4<$F14+$G14),1,"") | Q14: =IF(AND(Q$4>=$F14,Q$4<$F14+$G14),1,"")
A15: 11 | B15: 5. Arquitectura | C15: Documentar lenguaje, librerias y modulos con sus propositos | D15: 1 pagina cerrada | E15: 18 | F15: 6 | G15: 1 | H15: =F15+G15-1 -> 6 | I15: Si | J15: =IF(AND(J$4>=$F15,J$4<$F15+$G15),1,"") | K15: =IF(AND(K$4>=$F15,K$4<$F15+$G15),1,"") | L15: =IF(AND(L$4>=$F15,L$4<$F15+$G15),1,"") | M15: =IF(AND(M$4>=$F15,M$4<$F15+$G15),1,"") | N15: =IF(AND(N$4>=$F15,N$4<$F15+$G15),1,"") | O15: =IF(AND(O$4>=$F15,O$4<$F15+$G15),1,"") -> 1 | P15: =IF(AND(P$4>=$F15,P$4<$F15+$G15),1,"") | Q15: =IF(AND(Q$4>=$F15,Q$4<$F15+$G15),1,"")
A16: 12 | B16: 6. Datos de Entrada | C16: Listar archivos requeridos y sus tipos | D16: Seccion redactada | E16: 19 | F16: 4 | G16: 1 | H16: =F16+G16-1 -> 4 | I16: Si | J16: =IF(AND(J$4>=$F16,J$4<$F16+$G16),1,"") | K16: =IF(AND(K$4>=$F16,K$4<$F16+$G16),1,"") | L16: =IF(AND(L$4>=$F16,L$4<$F16+$G16),1,"") | M16: =IF(AND(M$4>=$F16,M$4<$F16+$G16),1,"") -> 1 | N16: =IF(AND(N$4>=$F16,N$4<$F16+$G16),1,"") | O16: =IF(AND(O$4>=$F16,O$4<$F16+$G16),1,"") | P16: =IF(AND(P$4>=$F16,P$4<$F16+$G16),1,"") | Q16: =IF(AND(Q$4>=$F16,Q$4<$F16+$G16),1,"")
... A32: 28 | B32: 10. Cierre | C32: Revision cruzada: cada integrante revisa lo que no escribio | D32: Checklist firmado | E32: 35 | F32: 7 | G32: 1 | H32: =F32+G32-1 -> 7 | I32: Si | J32: =IF(AND(J$4>=$F32,J$4<$F32+$G32),1,"") | K32: =IF(AND(K$4>=$F32,K$4<$F32+$G32),1,"") | L32: =IF(AND(L$4>=$F32,L$4<$F32+$G32),1,"") | M32: =IF(AND(M$4>=$F32,M$4<$F32+$G32),1,"") | N32: =IF(AND(N$4>=$F32,N$4<$F32+$G32),1,"") | O32: =IF(AND(O$4>=$F32,O$4<$F32+$G32),1,"") | P32: =IF(AND(P$4>=$F32,P$4<$F32+$G32),1,"") -> 1 | Q32: =IF(AND(Q$4>=$F32,Q$4<$F32+$G32),1,"")
A34: Naranjo = ruta critica. Gris = tiene holgura. Amarillo = celda editable.
A35: Ninguna subtarea se marca terminada sin su artefacto.

Sheet Informe Academico
A1: Carta Gantt - Informe Academico
A2: Subtareas que componen este entregable. La columna 'Tarea maestra' apunta al ID de la hoja Carta Gantt.
J3: Semana
A4: ID | B4: Seccion | C4: Subtarea | D4: Artefacto | E4: Tarea maestra | F4: Inicio | G4: Duracion | H4: Fin | I4: Critica | J4: 1 | K4: 2 | L4: 3 | M4: 4 | N4: 5 | O4: 6 | P4: 7 | Q4: 8
A5: 1 | B5: 1. Introduccion | C5: Redactar descripcion general del problema con las particularidades del grupo | D5: Seccion redactada | E5: 12 | F5: 3 | G5: 1 | H5: =F5+G5-1 -> 3 | I5: Si | J5: =IF(AND(J$4>=$F5,J$4<$F5+$G5),1,"") | K5: =IF(AND(K$4>=$F5,K$4<$F5+$G5),1,"") | L5: =IF(AND(L$4>=$F5,L$4<$F5+$G5),1,"") -> 1 | M5: =IF(AND(M$4>=$F5,M$4<$F5+$G5),1,"") | N5: =IF(AND(N$4>=$F5,N$4<$F5+$G5),1,"") | O5: =IF(AND(O$4>=$F5,O$4<$F5+$G5),1,"") | P5: =IF(AND(P$4>=$F5,P$4<$F5+$G5),1,"") | Q5: =IF(AND(Q$4>=$F5,Q$4<$F5+$G5),1,"")
A6: 2 | B6: 1. Introduccion | C6: Redactar objetivo general, objetivos especificos y entregables | D6: Seccion redactada | E6: 12 | F6: 3 | G6: 1 | H6: =F6+G6-1 -> 3 | I6: Si | J6: =IF(AND(J$4>=$F6,J$4<$F6+$G6),1,"") | K6: =IF(AND(K$4>=$F6,K$4<$F6+$G6),1,"") | L6: =IF(AND(L$4>=$F6,L$4<$F6+$G6),1,"") -> 1 | M6: =IF(AND(M$4>=$F6,M$4<$F6+$G6),1,"") | N6: =IF(AND(N$4>=$F6,N$4<$F6+$G6),1,"") | O6: =IF(AND(O$4>=$F6,O$4<$F6+$G6),1,"") | P6: =IF(AND(P$4>=$F6,P$4<$F6+$G6),1,"") | Q6: =IF(AND(Q$4>=$F6,Q$4<$F6+$G6),1,"")
A7: 3 | B7: 2. Proceso de Desarrollo | C7: Comparar planificacion inicial contra la ejecutada | D7: Seccion con la carta Gantt real | E7: 29 | F7: 7 | G7: 1 | H7: =F7+G7-1 -> 7 | I7: Si | J7: =IF(AND(J$4>=$F7,J$4<$F7+$G7),1,"") | K7: =IF(AND(K$4>=$F7,K$4<$F7+$G7),1,"") | L7: =IF(AND(L$4>=$F7,L$4<$F7+$G7),1,"") | M7: =IF(AND(M$4>=$F7,M$4<$F7+$G7),1,"") | N7: =IF(AND(N$4>=$F7,N$4<$F7+$G7),1,"") | O7: =IF(AND(O$4>=$F7,O$4<$F7+$G7),1,"") | P7: =IF(AND(P$4>=$F7,P$4<$F7+$G7),1,"") -> 1 | Q7: =IF(AND(Q$4>=$F7,Q$4<$F7+$G7),1,"")
A8: 4 | B8: 2. Proceso de Desarrollo | C8: Redactar decisiones clave, aciertos y errores | D8: Seccion redactada | E8: 29 | F8: 7 | G8: 1 | H8: =F8+G8-1 -> 7 | I8: Si | J8: =IF(AND(J$4>=$F8,J$4<$F8+$G8),1,"") | K8: =IF(AND(K$4>=$F8,K$4<$F8+$G8),1,"") | L8: =IF(AND(L$4>=$F8,L$4<$F8+$G8),1,"") | M8: =IF(AND(M$4>=$F8,M$4<$F8+$G8),1,"") | N8: =IF(AND(N$4>=$F8,N$4<$F8+$G8),1,"") | O8: =IF(AND(O$4>=$F8,O$4<$F8+$G8),1,"") | P8: =IF(AND(P$4>=$F8,P$4<$F8+$G8),1,"") -> 1 | Q8: =IF(AND(Q$4>=$F8,Q$4<$F8+$G8),1,"")
A9: 5 | B9: 3. Contexto y Planteamiento | C9: Redactar descripcion del problema y condiciones de referencia | D9: Seccion redactada | E9: 12 | F9: 3 | G9: 1 | H9: =F9+G9-1 -> 3 | I9: Si | J9: =IF(AND(J$4>=$F9,J$4<$F9+$G9),1,"") | K9: =IF(AND(K$4>=$F9,K$4<$F9+$G9),1,"") | L9: =IF(AND(L$4>=$F9,L$4<$F9+$G9),1,"") -> 1 | M9: =IF(AND(M$4>=$F9,M$4<$F9+$G9),1,"") | N9: =IF(AND(N$4>=$F9,N$4<$F9+$G9),1,"") | O9: =IF(AND(O$4>=$F9,O$4<$F9+$G9),1,"") | P9: =IF(AND(P$4>=$F9,P$4<$F9+$G9),1,"") | Q9: =IF(AND(Q$4>=$F9,Q$4<$F9+$G9),1,"")
A10: 6 | B10: 3. Contexto y Planteamiento | C10: Documentar los KPIs definidos y por que no se limitan al resultado basico | D10: Tabla de KPIs justificada | E10: 13 | F10: 3 | G10: 1 | H10: =F10+G10-1 -> 3 | I10: Si | J10: =IF(AND(J$4>=$F10,J$4<$F10+$G10),1,"") | K10: =IF(AND(K$4>=$F10,K$4<$F10+$G10),1,"") | L10: =IF(AND(L$4>=$F10,L$4<$F10+$G10),1,"") -> 1 | M10: =IF(AND(M$4>=$F10,M$4<$F10+$G10),1,"") | N10: =IF(AND(N$4>=$F10,N$4<$F10+$G10),1,"") | O10: =IF(AND(O$4>=$F10,O$4<$F10+$G10),1,"") | P10: =IF(AND(P$4>=$F10,P$4<$F10+$G10),1,"") | Q10: =IF(AND(Q$4>=$F10,Q$4<$F10+$G10),1,"")
A11: 7 | B11: 3. Contexto y Planteamiento | C11: Redactar supuestos iniciales y simplificaciones, con justificacion | D11: Seccion redactada | E11: 1 | F11: 3 | G11: 1 | H11: =F11+G11-1 -> 3 | I11: Si | J11: =IF(AND(J$4>=$F11,J$4<$F11+$G11),1,"") | K11: =IF(AND(K$4>=$F11,K$4<$F11+$G11),1,"") | L11: =IF(AND(L$4>=$F11,L$4<$F11+$G11),1,"") -> 1 | M11: =IF(AND(M$4>=$F11,M$4<$F11+$G11),1,"") | N11: =IF(AND(N$4>=$F11,N$4<$F11+$G11),1,"") | O11: =IF(AND(O$4>=$F11,O$4<$F11+$G11),1,"") | P11: =IF(AND(P$4>=$F11,P$4<$F11+$G11),1,"") | Q11: =IF(AND(Q$4>=$F11,Q$4<$F11+$G11),1,"")
A12: 8 | B12: 4. Tratamiento de Datos | C12: Redactar como se convirtieron los datos originales en informacion util | D12: Seccion redactada | E12: 7 | F12: 3 | G12: 1 | H12: =F12+G12-1 -> 3 | I12: Si | J12: =IF(AND(J$4>=$F12,J$4<$F12+$G12),1,"") | K12: =IF(AND(K$4>=$F12,K$4<$F12+$G12),1,"") | L12: =IF(AND(L$4>=$F12,L$4<$F12+$G12),1,"") -> 1 | M12: =IF(AND(M$4>=$F12,M$4<$F12+$G12),1,"") | N12: =IF(AND(N$4>=$F12,N$4<$F12+$G12),1,"") | O12: =IF(AND(O$4>=$F12,O$4<$F12+$G12),1,"") | P12: =IF(AND(P$4>=$F12,P$4<$F12+$G12),1,"") | Q12: =IF(AND(Q$4>=$F12,Q$4<$F12+$G12),1,"")
A13: 9 | B13: 4. Tratamiento de Datos | C13: Documentar problemas encontrados: hojas ocultas, celdas inconsistentes | D13: Seccion redactada | E13: 7 | F13: 4 | G13: 1 | H13: =F13+G13-1 -> 4 | I13: Si | J13: =IF(AND(J$4>=$F13,J$4<$F13+$G13),1,"") | K13: =IF(AND(K$4>=$F13,K$4<$F13+$G13),1,"") | L13: =IF(AND(L$4>=$F13,L$4<$F13+$G13),1,"") | M13: =IF(AND(M$4>=$F13,M$4<$F13+$G13),1,"") -> 1 | N13: =IF(AND(N$4>=$F13,N$4<$F13+$G13),1,"") | O13: =IF(AND(O$4>=$F13,O$4<$F13+$G13),1,"") | P13: =IF(AND(P$4>=$F13,P$4<$F13+$G13),1,"") | Q13: =IF(AND(Q$4>=$F13,Q$4<$F13+$G13),1,"")
A14: 10 | B14: 4. Tratamiento de Datos | C14: Tabular parametros de proceso con rangos minimo, maximo y habitual | D14: Tabla de parametros | E14: 26 | F14: 6 | G14: 1 | H14: =F14+G14-1 -> 6 | I14: Si | J14: =IF(AND(J$4>=$F14,J$4<$F14+$G14),1,"") | K14: =IF(AND(K$4>=$F14,K$4<$F14+$G14),1,"") | L14: =IF(AND(L$4>=$F14,L$4<$F14+$G14),1,"") | M14: =IF(AND(M$4>=$F14,M$4<$F14+$G14),1,"") | N14: =IF(AND(N$4>=$F14,N$4<$F14+$G14),1,"") | O14: =IF(AND(O$4>=$F14,O$4<$F14+$G14),1,"") -> 1 | P14: =IF(AND(P$4>=$F14,P$4<$F14+$G14),1,"") | Q14: =IF(AND(Q$4>=$F14,Q$4<$F14+$G14),1,"")
A15: 11 | B15: 4. Tratamiento de Datos | C15: Documentar diseno y construccion de las instancias de prueba | D15: Seccion redactada | E15: 17 | F15: 5 | G15: 1 | H15: =F15+G15-1 -> 5 | I15: Si | J15: =IF(AND(J$4>=$F15,J$4<$F15+$G15),1,"") | K15: =IF(AND(K$4>=$F15,K$4<$F15+$G15),1,"") | L15: =IF(AND(L$4>=$F15,L$4<$F15+$G15),1,"") | M15: =IF(AND(M$4>=$F15,M$4<$F15+$G15),1,"") | N15: =IF(AND(N$4>=$F15,N$4<$F15+$G15),1,"") -> 1 | O15: =IF(AND(O$4>=$F15,O$4<$F15+$G15),1,"") | P15: =IF(AND(P$4>=$F15,P$4<$F15+$G15),1,"") | Q15: =IF(AND(Q$4>=$F15,Q$4<$F15+$G15),1,"")
A16: 12 | B16: 4. Tratamiento de Datos | C16: Anexar el codigo del generador y los prompts usados para generarlo | D16: Anexo | E16: 17 | F16: 5 | G16: 1 | H16: =F16+G16-1 -> 5 | I16: Si | J16: =IF(AND(J$4>=$F16,J$4<$F16+$G16),1,"") | K16: =IF(AND(K$4>=$F16,K$4<$F16+$G16),1,"") | L16: =IF(AND(L$4>=$F16,L$4<$F16+$G16),1,"") | M16: =IF(AND(M$4>=$F16,M$4<$F16+$G16),1,"") | N16: =IF(AND(N$4>=$F16,N$4<$F16+$G16),1,"") -> 1 | O16: =IF(AND(O$4>=$F16,O$4<$F16+$G16),1,"") | P16: =IF(AND(P$4>=$F16,P$4<$F16+$G16),1,"") | Q16: =IF(AND(Q$4>=$F16,Q$4<$F16+$G16),1,"")
... A33: 29 | B33: 11. Cierre | C33: Armar referencias en APA 7 y revision cruzada final | D33: Documento armado | E33: 35 | F33: 7 | G33: 1 | H33: =F33+G33-1 -> 7 | I33: Si | J33: =IF(AND(J$4>=$F33,J$4<$F33+$G33),1,"") | K33: =IF(AND(K$4>=$F33,K$4<$F33+$G33),1,"") | L33: =IF(AND(L$4>=$F33,L$4<$F33+$G33),1,"") | M33: =IF(AND(M$4>=$F33,M$4<$F33+$G33),1,"") | N33: =IF(AND(N$4>=$F33,N$4<$F33+$G33),1,"") | O33: =IF(AND(O$4>=$F33,O$4<$F33+$G33),1,"") | P33: =IF(AND(P$4>=$F33,P$4<$F33+$G33),1,"") -> 1 | Q33: =IF(AND(Q$4>=$F33,Q$4<$F33+$G33),1,"")
A35: Naranjo = ruta critica. Gris = tiene holgura. Amarillo = celda editable.
A36: Ninguna subtarea se marca terminada sin su artefacto.

Sheet Pagina Web
A1: Carta Gantt - Pagina web y nucleo de optimizacion
A2: Subtareas que componen este entregable. La columna 'Tarea maestra' apunta al ID de la hoja Carta Gantt.
J3: Semana
A4: ID | B4: Seccion | C4: Subtarea | D4: Artefacto | E4: Tarea maestra | F4: Inicio | G4: Duracion | H4: Fin | I4: Critica | J4: 1 | K4: 2 | L4: 3 | M4: 4 | N4: 5 | O4: 6 | P4: 7 | Q4: 8
A5: 1 | B5: A. Decisiones tecnicas | C5: Elegir stack: framework web, solver y servicio de despliegue | D5: Decision documentada | E5: 11 | F5: 3 | G5: 1 | H5: =F5+G5-1 -> 3 | I5: Si | J5: =IF(AND(J$4>=$F5,J$4<$F5+$G5),1,"") | K5: =IF(AND(K$4>=$F5,K$4<$F5+$G5),1,"") | L5: =IF(AND(L$4>=$F5,L$4<$F5+$G5),1,"") -> 1 | M5: =IF(AND(M$4>=$F5,M$4<$F5+$G5),1,"") | N5: =IF(AND(N$4>=$F5,N$4<$F5+$G5),1,"") | O5: =IF(AND(O$4>=$F5,O$4<$F5+$G5),1,"") | P5: =IF(AND(P$4>=$F5,P$4<$F5+$G5),1,"") | Q5: =IF(AND(Q$4>=$F5,Q$4<$F5+$G5),1,"")
A6: 2 | B6: A. Decisiones tecnicas | C6: Definir la arquitectura de modulos y sus interfaces | D6: Diagrama de modulos | E6: 11 | F6: 3 | G6: 1 | H6: =F6+G6-1 -> 3 | I6: Si | J6: =IF(AND(J$4>=$F6,J$4<$F6+$G6),1,"") | K6: =IF(AND(K$4>=$F6,K$4<$F6+$G6),1,"") | L6: =IF(AND(L$4>=$F6,L$4<$F6+$G6),1,"") -> 1 | M6: =IF(AND(M$4>=$F6,M$4<$F6+$G6),1,"") | N6: =IF(AND(N$4>=$F6,N$4<$F6+$G6),1,"") | O6: =IF(AND(O$4>=$F6,O$4<$F6+$G6),1,"") | P6: =IF(AND(P$4>=$F6,P$4<$F6+$G6),1,"") | Q6: =IF(AND(Q$4>=$F6,Q$4<$F6+$G6),1,"")
A7: 3 | B7: B. Nucleo de optimizacion | C7: Implementar lectura y estructuras de datos base | D7: Modulo con pruebas | E7: 5 | F7: 3 | G7: 1 | H7: =F7+G7-1 -> 3 | I7: Si | J7: =IF(AND(J$4>=$F7,J$4<$F7+$G7),1,"") | K7: =IF(AND(K$4>=$F7,K$4<$F7+$G7),1,"") | L7: =IF(AND(L$4>=$F7,L$4<$F7+$G7),1,"") -> 1 | M7: =IF(AND(M$4>=$F7,M$4<$F7+$G7),1,"") | N7: =IF(AND(N$4>=$F7,N$4<$F7+$G7),1,"") | O7: =IF(AND(O$4>=$F7,O$4<$F7+$G7),1,"") | P7: =IF(AND(P$4>=$F7,P$4<$F7+$G7),1,"") | Q7: =IF(AND(Q$4>=$F7,Q$4<$F7+$G7),1,"")
A8: 4 | B8: B. Nucleo de optimizacion | C8: Implementar el packer 2D por capa con rotacion de 90 grados | D8: Modulo con pruebas | E8: 15 | F8: 3 | G8: 2 | H8: =F8+G8-1 -> 4 | I8: No | J8: =IF(AND(J$4>=$F8,J$4<$F8+$G8),1,"") | K8: =IF(AND(K$4>=$F8,K$4<$F8+$G8),1,"") | L8: =IF(AND(L$4>=$F8,L$4<$F8+$G8),1,"") -> 1 | M8: =IF(AND(M$4>=$F8,M$4<$F8+$G8),1,"") -> 1 | N8: =IF(AND(N$4>=$F8,N$4<$F8+$G8),1,"") | O8: =IF(AND(O$4>=$F8,O$4<$F8+$G8),1,"") | P8: =IF(AND(P$4>=$F8,P$4<$F8+$G8),1,"") | Q8: =IF(AND(Q$4>=$F8,Q$4<$F8+$G8),1,"")
A9: 5 | B9: B. Nucleo de optimizacion | C9: Implementar la asignacion carga-bodega-plan | D9: Modulo con pruebas | E9: 16 | F9: 3 | G9: 2 | H9: =F9+G9-1 -> 4 | I9: Si | J9: =IF(AND(J$4>=$F9,J$4<$F9+$G9),1,"") | K9: =IF(AND(K$4>=$F9,K$4<$F9+$G9),1,"") | L9: =IF(AND(L$4>=$F9,L$4<$F9+$G9),1,"") -> 1 | M9: =IF(AND(M$4>=$F9,M$4<$F9+$G9),1,"") -> 1 | N9: =IF(AND(N$4>=$F9,N$4<$F9+$G9),1,"") | O9: =IF(AND(O$4>=$F9,O$4<$F9+$G9),1,"") | P9: =IF(AND(P$4>=$F9,P$4<$F9+$G9),1,"") | Q9: =IF(AND(Q$4>=$F9,Q$4<$F9+$G9),1,"")
A10: 6 | B10: B. Nucleo de optimizacion | C10: Implementar la restriccion de no-overstowage por rotacion de puertos | D10: Prueba que falla si se viola | E10: 16 | F10: 3 | G10: 1 | H10: =F10+G10-1 -> 3 | I10: Si | J10: =IF(AND(J$4>=$F10,J$4<$F10+$G10),1,"") | K10: =IF(AND(K$4>=$F10,K$4<$F10+$G10),1,"") | L10: =IF(AND(L$4>=$F10,L$4<$F10+$G10),1,"") -> 1 | M10: =IF(AND(M$4>=$F10,M$4<$F10+$G10),1,"") | N10: =IF(AND(N$4>=$F10,N$4<$F10+$G10),1,"") | O10: =IF(AND(O$4>=$F10,O$4<$F10+$G10),1,"") | P10: =IF(AND(P$4>=$F10,P$4<$F10+$G10),1,"") | Q10: =IF(AND(Q$4>=$F10,Q$4<$F10+$G10),1,"")
A11: 7 | B11: B. Nucleo de optimizacion | C11: Implementar el calculo de makespan por cuadrilla y su minimizacion | D11: Modulo con pruebas | E11: 16 | F11: 4 | G11: 1 | H11: =F11+G11-1 -> 4 | I11: Si | J11: =IF(AND(J$4>=$F11,J$4<$F11+$G11),1,"") | K11: =IF(AND(K$4>=$F11,K$4<$F11+$G11),1,"") | L11: =IF(AND(L$4>=$F11,L$4<$F11+$G11),1,"") | M11: =IF(AND(M$4>=$F11,M$4<$F11+$G11),1,"") -> 1 | N11: =IF(AND(N$4>=$F11,N$4<$F11+$G11),1,"") | O11: =IF(AND(O$4>=$F11,O$4<$F11+$G11),1,"") | P11: =IF(AND(P$4>=$F11,P$4<$F11+$G11),1,"") | Q11: =IF(AND(Q$4>=$F11,Q$4<$F11+$G11),1,"")
A12: 8 | B12: B. Nucleo de optimizacion | C12: Implementar limite de tiempo de resolucion y retorno de mejor solucion | D12: Parametro configurable | E12: 27 | F12: 4 | G12: 1 | H12: =F12+G12-1 -> 4 | I12: No | J12: =IF(AND(J$4>=$F12,J$4<$F12+$G12),1,"") | K12: =IF(AND(K$4>=$F12,K$4<$F12+$G12),1,"") | L12: =IF(AND(L$4>=$F12,L$4<$F12+$G12),1,"") | M12: =IF(AND(M$4>=$F12,M$4<$F12+$G12),1,"") -> 1 | N12: =IF(AND(N$4>=$F12,N$4<$F12+$G12),1,"") | O12: =IF(AND(O$4>=$F12,O$4<$F12+$G12),1,"") | P12: =IF(AND(P$4>=$F12,P$4<$F12+$G12),1,"") | Q12: =IF(AND(Q$4>=$F12,Q$4<$F12+$G12),1,"")
A13: 9 | B13: B. Nucleo de optimizacion | C13: Construir el generador de instancias sinteticas | D13: Script + instancias | E13: 17 | F13: 4 | G13: 2 | H13: =F13+G13-1 -> 5 | I13: Si | J13: =IF(AND(J$4>=$F13,J$4<$F13+$G13),1,"") | K13: =IF(AND(K$4>=$F13,K$4<$F13+$G13),1,"") | L13: =IF(AND(L$4>=$F13,L$4<$F13+$G13),1,"") | M13: =IF(AND(M$4>=$F13,M$4<$F13+$G13),1,"") -> 1 | N13: =IF(AND(N$4>=$F13,N$4<$F13+$G13),1,"") -> 1 | O13: =IF(AND(O$4>=$F13,O$4<$F13+$G13),1,"") | P13: =IF(AND(P$4>=$F13,P$4<$F13+$G13),1,"") | Q13: =IF(AND(Q$4>=$F13,Q$4<$F13+$G13),1,"")
A14: 10 | B14: B. Nucleo de optimizacion | C14: Prueba de integracion temprana: esqueleto de punta a punta con salida cruda | D14: Script que corre de archivo a resultado | E14: 18 | F14: 4 | G14: 1 | H14: =F14+G14-1 -> 4 | I14: Si | J14: =IF(AND(J$4>=$F14,J$4<$F14+$G14),1,"") | K14: =IF(AND(K$4>=$F14,K$4<$F14+$G14),1,"") | L14: =IF(AND(L$4>=$F14,L$4<$F14+$G14),1,"") | M14: =IF(AND(M$4>=$F14,M$4<$F14+$G14),1,"") -> 1 | N14: =IF(AND(N$4>=$F14,N$4<$F14+$G14),1,"") | O14: =IF(AND(O$4>=$F14,O$4<$F14+$G14),1,"") | P14: =IF(AND(P$4>=$F14,P$4<$F14+$G14),1,"") | Q14: =IF(AND(Q$4>=$F14,Q$4<$F14+$G14),1,"")
A15: 11 | B15: C. Entrada de datos | C15: Disenar el esquema de entrada: tonelaje por bodega, destinos y productos | D15: Especificacion escrita | E15: 19 | F15: 4 | G15: 1 | H15: =F15+G15-1 -> 4 | I15: Si | J15: =IF(AND(J$4>=$F15,J$4<$F15+$G15),1,"") | K15: =IF(AND(K$4>=$F15,K$4<$F15+$G15),1,"") | L15: =IF(AND(L$4>=$F15,L$4<$F15+$G15),1,"") | M15: =IF(AND(M$4>=$F15,M$4<$F15+$G15),1,"") -> 1 | N15: =IF(AND(N$4>=$F15,N$4<$F15+$G15),1,"") | O15: =IF(AND(O$4>=$F15,O$4<$F15+$G15),1,"") | P15: =IF(AND(P$4>=$F15,P$4<$F15+$G15),1,"") | Q15: =IF(AND(Q$4>=$F15,Q$4<$F15+$G15),1,"")
A16: 12 | B16: C. Entrada de datos | C16: Definir reglas de validacion y mensajes de error legibles | D16: Tabla de reglas | E16: 19 | F16: 4 | G16: 1 | H16: =F16+G16-1 -> 4 | I16: Si | J16: =IF(AND(J$4>=$F16,J$4<$F16+$G16),1,"") | K16: =IF(AND(K$4>=$F16,K$4<$F16+$G16),1,"") | L16: =IF(AND(L$4>=$F16,L$4<$F16+$G16),1,"") | M16: =IF(AND(M$4>=$F16,M$4<$F16+$G16),1,"") -> 1 | N16: =IF(AND(N$4>=$F16,N$4<$F16+$G16),1,"") | O16: =IF(AND(O$4>=$F16,O$4<$F16+$G16),1,"") | P16: =IF(AND(P$4>=$F16,P$4<$F16+$G16),1,"") | Q16: =IF(AND(Q$4>=$F16,Q$4<$F16+$G16),1,"")
... A31: 27 | B31: G. Entrega | C31: Congelamiento: desde aqui solo correccion de errores | D31: Version etiquetada | E31: 28 | F31: 7 | G31: 1 | H31: =F31+G31-1 -> 7 | I31: Si | J31: =IF(AND(J$4>=$F31,J$4<$F31+$G31),1,"") | K31: =IF(AND(K$4>=$F31,K$4<$F31+$G31),1,"") | L31: =IF(AND(L$4>=$F31,L$4<$F31+$G31),1,"") | M31: =IF(AND(M$4>=$F31,M$4<$F31+$G31),1,"") | N31: =IF(AND(N$4>=$F31,N$4<$F31+$G31),1,"") | O31: =IF(AND(O$4>=$F31,O$4<$F31+$G31),1,"") | P31: =IF(AND(P$4>=$F31,P$4<$F31+$G31),1,"") -> 1 | Q31: =IF(AND(Q$4>=$F31,Q$4<$F31+$G31),1,"")
A33: Naranjo = ruta critica. Gris = tiene holgura. Amarillo = celda editable.
A34: Ninguna subtarea se marca terminada sin su artefacto.

Sheet Aportes
A1: ID | B1: Tarea maestra | C1: Inf. Tecnico | D1: Inf. Academico | E1: Pagina web
A2: 1 | B2: Registro de supuestos: los 6 no resueltos, con justificacion e impacto | C2: 0.03 | D2: 0.05 | E2: 0
A3: 2 | B3: Congelar el caso base: Kiwi Arrow, hoja PRESTOW N 06 | C3: 0 | D3: 0.02 | E3: 0
A4: 3 | B4: Escribir la propuesta de valor: velocidad y repetibilidad, no mejor calidad | C4: 0.04 | D4: 0.03 | E4: 0
A5: 4 | B5: Desocultar hojas y separar Kiwi Arrow de Misago y Eagle Arrow | C5: 0 | D5: 0 | E5: 0
A6: 5 | B6: Extraer el prestow a CSV estructurado | C6: 0 | D6: 0.03 | E6: 0.04
A7: 6 | B7: Leer los dibujos de planimetria y tabular unidades por plan | C7: 0 | D7: 0.05 | E7: 0.06
A8: 7 | B8: Registrar inconsistencias entre celdas auxiliares y dibujos | C8: 0 | D8: 0.04 | E8: 0
A9: 8 | B9: Diccionario de datos: campos, tipos, rangos y reglas | C9: 0.08 | D9: 0 | E9: 0.04
A10: 9 | B10: Leer el survey de estiba y 4 a 6 trabajos adicionales | C10: 0 | D10: 0.06 | E10: 0
A11: 10 | B11: Tabla comparativa modelo / objetivo / metodo / aplicabilidad a Lirquen | C11: 0 | D11: 0.06 | E11: 0
A12: 11 | B12: Seleccion analitica del metodo, con pros, contras y justificacion | C12: 0.1 | D12: 0.1 | E12: 0
A13: 12 | B13: Definir funcion objetivo y alcance del sistema (que hace y que NO hace) | C13: 0.06 | D13: 0.04 | E13: 0
... A37: 36 | B37: Semana de colchon: solo correcciones, cero funcionalidad nueva | C37: 0 | D37: 0 | E37: 0
B38: TOTAL (debe dar 100%) | C38: =SUM(C2:C37) -> 1 | D38: =SUM(D2:D37) -> 1 | E38: =SUM(E2:E37) -> 1
B40: Reparto propuesto, no una verdad. Ajustenlo: la unica regla es que cada columna sume 100%.
